Workbook

Sheet Portfolio Details
G2: Investment | H2: 100000
B3: Asset Allocation | G3: Date | H3: 44599
B4: Asset | C4: Returns ( E ) | D4: Allocation | E4: Std Dev | G4: Instrument | H4: Weightage | I4: Rate | J4: Units | L4: Absolute Returns (%) | M4: =J25/J13-1 -> 1.1802538
B5: Goldbees | C5: =0.7*Info!D3 -> 0.1776657 | D5: 0.2 | E5: =Info!F3 -> 0.17598315 | G5: Goldbees | H5: 0.2 | I5: 41.63 | J5: 480
B6: Silverbees | C6: =0.55*Info!D4 -> 0.20437599 | D6: 0.05 | E6: =Info!F4 -> 0.3347856 | G6: Silverbees | H6: 0.05 | I6: 61.77 | J6: 80 | L6: CAGR (%) | M6: =(1+M4)^(1/4)-1 -> 0.21514124
B7: Giltbees | C7: =Info!D6 -> 0.058325041 | D7: 0.05 | E7: =Info!F6 -> 0.045040009 | G7: Giltbees | H7: 0.05 | I7: 49.12 | J7: 101
B8: Bankbees | C8: =Info!D7 -> 0.10374126 | D8: 0.2 | E8: =Info!F7 -> 0.15734723 | G8: Bankbees | H8: 0.2 | I8: 383.06 | J8: 52
B9: Hangseng | C9: =Info!D11 -> 0.087918962 | D9: 0.15772307 | E9: =Info!F11 -> 0.26470009 | G9: Hangseng | H9: 0.15772307 | I9: 309.6 | J9: 50
B10: Nasdaq | C10: =0.7*Info!D12 -> 0.18183297 | D10: 0.092276932 | E10: =Info!F12 -> 0.20819876 | G10: Nasdaq | H10: 0.092276932 | I10: 104.29 | J10: 88
B11: Itbees | C11: =Info!C8 -> 0.061413951 | D11: 0.05 | E11: =Info!F8 -> 0.20562586 | G11: Itbees | H11: 0.05 | I11: 35.69 | J11: 140
B12: Healthy | C12: =Info!D9 -> 0.13433511 | D12: 0.2 | E12: =Info!F9 -> 0.14471859 | G12: Healthy | H12: 0.2 | I12: 8.37 | J12: 2389
B13: Total | D13: =SUM(D5:D12) -> 1 | I13: Total | J13: 99454.29
B14: Portfolio Return (e) | C14: =C5*D5+C6*D6+C7*D7+C8*D8+C9*D9+C10*D10+C11*D11+C12*D12 -> 0.13
B15: Portfolio Risk | C15: =Covariance!I15 -> 0.099778246 | G15: Date | H15: 46167
B16: Sharpe Ratio | C16: =(C14-6%)/C15 -> 0.70155573 | G16: Instrument | H16: Weightage | I16: Rate | J16: Units
B17: Beta | C17: ='Portfolio Returns'!I9 -> 0.19744577 | G17: Goldbees | H17: 0.2 | I17: 130.51 | J17: 480
B18: Average Annualized Rolling Return (e) | C18: ='Portfolio Returns'!I10*12 -> 0.16944975 | G18: Silverbees | H18: 0.05 | I18: 256.03 | J18: 80
G19: Giltbees | H19: 0.05 | I19: 49.12 | J19: 101
B20: Max Drawdown | C20: ='Portfolio Returns'!F1029 -> -0.11270683 | G20: Bankbees | H20: 0.2 | I20: 571.02 | J20: 52
G21: Hangseng | H21: 0.15772307 | I21: 536.43 | J21: 50
G22: Nasdaq | H22: 0.092276932 | I22: 330.7 | J22: 88
G23: Itbees | H23: 0.05 | I23: 32.15 | J23: 140
G24: Healthy | H24: 0.2 | I24: 16.17 | J24: 2389
I25: Total | J25: 216835.59

Sheet Info
C2: Average Annual Returns% | D2: CAGR (%) | E2: Risk Daily | F2: Risk Annual
B3: GOLDBEES | C3: =Goldbees!$M$6 -> 0.24493942 | D3: =Goldbees!$M$8 -> 0.25380814 | E3: =Goldbees!$M$10 -> 0.011085896 | F3: =SQRT(252)*E3 -> 0.17598315
B4: SILVERBEES | C4: =Silverbees!$M$6 -> 0.39583379 | D4: =Silverbees!$M$8 -> 0.37159271 | E4: =Silverbees!$M$10 -> 0.021089511 | F4: =SQRT(252)*E4 -> 0.3347856
B5: AUTOBEES | C5: =Autobees!$P$6 -> 0.21729515 | D5: =Autobees!$P$8 -> 0.18581998 | E5: =Autobees!$P$10 -> 0.011694926 | F5: =SQRT(252)*E5 -> 0.18565119
B6: GILTBEES | C6: =Giltbees!$M$6 -> 0.059133958 | D6: =Giltbees!$M$8 -> 0.058325041 | E6: =Giltbees!$M$10 -> 0.0028372539 | F6: =SQRT(252)*E6 -> 0.045040009
B7: BANKBEES | C7: =Bankbees!$M$6 -> 0.1113408 | D7: =Bankbees!$M$8 -> 0.10374126 | E7: =Bankbees!$M$10 -> 0.0099119438 | F7: =SQRT(252)*E7 -> 0.15734723
B8: ITBEES | C8: =ITbees!$M$6 -> 0.061413951 | D8: =ITbees!$M$8 -> 0.038627621 | E8: =ITbees!$M$10 -> 0.012953212 | F8: =SQRT(252)*E8 -> 0.20562586
B9: HEALTHY | C9: =Healthy!$M$6 -> 0.14709971 | D9: =Healthy!$M$8 -> 0.13433511 | E9: =Healthy!$M$10 -> 0.009116414 | F9: =SQRT(252)*E9 -> 0.14471859
B10: COMMODITY | C10: =Commodity!$M$6 -> 0.17643207 | D10: =Commodity!$M$8 -> 0.16683458 | E10: =Commodity!$M$10 -> 0.010388264 | F10: =SQRT(252)*E10 -> 0.16490858
B11: HANGSENGBEES | C11: =Hangseng!$M$6 -> 0.12042584 | D11: =Hangseng!$M$8 -> 0.087918962 | E11: =Hangseng!$M$10 -> 0.016674539 | F11: =SQRT(252)*E11 -> 0.26470009
B12: NASDAQ | C12: =Nasdaq!$M$6 -> 0.26644675 | D12: =Nasdaq!$M$8 -> 0.25976138 | E12: =Nasdaq!$M$10 -> 0.013115289 | F12: =SQRT(252)*E12 -> 0.20819876

Sheet Correlation
C2: GOLDBEES | D2: SILVERBEES | E2: AUTOBEES | F2: GILTBEES | G2: BANKBEES | H2: ITBEES | I2: HEALTHY | J2: COMMODITY | K2: HANGSENGBEES | L2: NASDAQ
B3: GOLDBEES | C3: 1 | D3: =CORREL(Goldbees!H179:H1242,Silverbees!H2:H1065) -> 0.80411704 | E3: =CORREL(Goldbees!H171:H1242,Autobees!H2:H1073) -> 0.039170073 | F3: =CORREL(Goldbees!H2:H1239,Giltbees!H2:H1239) -> 0.01361839 | G3: =CORREL(Goldbees!H2:H1242,Bankbees!H2:H1242) -> 0.055789323 | H3: =CORREL(Goldbees!H2:H1242,ITbees!H2:H1242) -> 0.013916586 | I3: =CORREL(Goldbees!H110:H1242,Healthy!H2:H1134) -> 0.027608071 | J3: =CORREL(Goldbees!H396:H1242,Commodity!H2:H848) -> 0.17841456 | K3: =CORREL(Goldbees!H2:H1242,Hangseng!H2:H1242) -> 0.15453216 | L3: =CORREL(Goldbees!H20:H1242,Nasdaq!H2:H1224) -> 0.089795716
B4: SILVERBEES | C4: =D$3 -> 0.80411704 | D4: 1 | E4: =CORREL(Silverbees!H2:H1065,Autobees!H10:H1073) -> 0.10924088 | F4: =CORREL(Silverbees!H2:H1065,Giltbees!H176:H1239) -> 0.0025663643 | G4: =CORREL(Silverbees!H2:H1065,Bankbees!H179:H1242) -> 0.14601604 | H4: =CORREL(Silverbees!H2:H1065,ITbees!H179:H1242) -> 0.11151837 | I4: =CORREL(Silverbees!H2:H1065,Healthy!H71:H1134) -> 0.088590727 | J4: =CORREL(Silverbees!H219:H1065,Commodity!H2:H848) -> 0.23268892 | K4: =CORREL(Silverbees!H2:H1065,Hangseng!H179:H1242) -> 0.24254293 | L4: =CORREL(Silverbees!H2:H1065,Nasdaq!H179:H1242) -> 0.0091920551
B5: AUTOBEES | C5: =E$3 -> 0.039170073 | D5: =E4 -> 0.10924088 | E5: 1 | F5: =CORREL(Autobees!H2:H1073,Giltbees!H168:H1239) -> 0.063627916 | G5: =CORREL(Autobees!H2:H1073,Bankbees!H171:H1242) -> 0.61377168 | H5: =CORREL(Autobees!H2:H1073,ITbees!H171:H1242) -> 0.35042079 | I5: =CORREL(Autobees!H2:H1073,Healthy!H63:H1134) -> 0.48185375 | J5: =CORREL(Autobees!H227:H1073,Commodity!H2:H848) -> 0.62713817 | K5: =CORREL(Autobees!H2:H1073,Hangseng!H171:H1242) -> 0.16096424 | L5: =CORREL(Autobees!H2:H1073,Nasdaq!H171:H1242) -> 0.036726218
B6: GILTBEES | C6: =F$3 -> 0.01361839 | D6: =F4 -> 0.0025663643 | E6: =F5 -> 0.063627916 | F6: 1 | G6: =CORREL(Giltbees!H2:H1242,Bankbees!H2:H1242) -> 0.018176665 | H6: =CORREL(Giltbees!H2:H1242,ITbees!H2:H1242) -> -0.008605414 | I6: =CORREL(Giltbees!H107:H1239,Healthy!H2:H1134) -> 0.011692671 | J6: =CORREL(Giltbees!H393:H1239,Commodity!H2:H848) -> 0.12143294 | K6: =CORREL(Giltbees!H2:H1239,Hangseng!H2:H1239) -> 0.068310588 | L6: =CORREL(Giltbees!H2:H1239,Nasdaq!H2:H1239) -> -0.032833086
B7: BANKBEES | C7: =G$3 -> 0.055789323 | D7: =G4 -> 0.14601604 | E7: =G5 -> 0.61377168 | F7: =G6 -> 0.018176665 | G7: 1 | H7: =CORREL(Bankbees!H2:H1242,ITbees!H2:H1242) -> 0.34825987 | I7: =CORREL(Bankbees!H110:H1242,Healthy!H2:H1134) -> 0.37353774 | J7: =CORREL(Bankbees!H396:H1242,Commodity!H2:H848) -> 0.63347751 | K7: =CORREL(Bankbees!H2:H1242,Hangseng!H2:H1242) -> 0.18039668 | L7: =CORREL(Bankbees!H2:H1242,Nasdaq!H2:H1242) -> 0.004645203
B8: ITBEES | C8: =H$3 -> 0.013916586 | D8: =H4 -> 0.11151837 | E8: =H5 -> 0.35042079 | F8: =H6 -> -0.008605414 | G8: =H7 -> 0.34825987 | H8: 1 | I8: =CORREL(ITbees!H110:H1242,Healthy!H2:H1134) -> 0.36172567 | J8: =CORREL(ITbees!H396:H1242,Commodity!H2:H848) -> 0.30615896 | K8: =CORREL(ITbees!H2:H1242,Hangseng!H2:H1242) -> 0.15116711 | L8: =CORREL(ITbees!H2:H1242,Nasdaq!H2:H1242) -> 0.040528798
B9: HEALTHY | C9: =I$3 -> 0.027608071 | D9: =I4 -> 0.088590727 | E9: =I5 -> 0.48185375 | F9: =I6 -> 0.011692671 | G9: =I7 -> 0.37353774 | H9: =I8 -> 0.36172567 | I9: 1 | J9: =CORREL(Healthy!H288:H1134,Commodity!H2:H848) -> 0.46510468 | K9: =CORREL(Healthy!H2:H1134,Hangseng!H110:H1242) -> 0.11565331 | L9: =CORREL(Healthy!H2:H1134,Nasdaq!H110:H1242) -> 0.038727798
B10: COMMODITY | C10: =J$3 -> 0.17841456 | D10: =J4 -> 0.23268892 | E10: =J5 -> 0.62713817 | F10: =J6 -> 0.12143294 | G10: =J7 -> 0.63347751 | H10: =J8 -> 0.30615896 | I10: =J9 -> 0.46510468 | J10: 1 | K10: =CORREL(Commodity!H2:H848,Hangseng!H396:H1242) -> 0.24095058 | L10: =CORREL(Commodity!H2:H848,Nasdaq!H396:H1242) -> 0.053573522
B11: HANGSENGBEES | C11: =K$3 -> 0.15453216 | D11: =K4 -> 0.24254293 | E11: =K5 -> 0.16096424 | F11: =K6 -> 0.068310588 | G11: =K7 -> 0.18039668 | H11: =K8 -> 0.15116711 | I11: =K9 -> 0.11565331 | J11: =K10 -> 0.24095058 | K11: 1 | L11: =CORREL(Hangseng!H2:H1242,Nasdaq!H2:H1242) -> 0.0033080838
B12: NASDAQ | C12: =L$3 -> 0.089795716 | D12: =L4 -> 0.0091920551 | E12: =L5 -> 0.036726218 | F12: =L6 -> -0.032833086 | G12: =L7 -> 0.004645203 | H12: =L8 -> 0.040528798 | I12: =L9 -> 0.038727798 | J12: =L10 -> 0.053573522 | K12: =L11 -> 0.0033080838 | L12: 1

Sheet Covariance
C3: Goldbees | D3: Silverbees | E3: Giltbees | F3: Bankbees | G3: Hangseng | H3: Nasdaq | I3: Itbees | J3: Healthy
B4: Goldbees | C4: ='Portfolio Details'!E5*'Portfolio Details'!E5*Correlation!C3 -> 0.030970068 | D4: ='Portfolio Details'!E5*'Portfolio Details'!E6*Correlation!D3 -> 0.047375862 | E4: ='Portfolio Details'!E5*'Portfolio Details'!E7*Correlation!F3 -> 0.00010794321 | F4: ='Portfolio Details'!E5*'Portfolio Details'!E8*Correlation!G3 -> 0.0015448321 | G4: ='Portfolio Details'!E5*'Portfolio Details'!E9*Correlation!K3 -> 0.007198534 | H4: ='Portfolio Details'!E5*'Portfolio Details'!E10*Correlation!L3 -> 0.0032900677 | I4: ='Portfolio Details'!E5*'Portfolio Details'!E11*Correlation!H3 -> 0.00050359514 | J4: ='Portfolio Details'!E5*'Portfolio Details'!E12*Correlation!I3 -> 0.00070312324
B5: Silverbees | C5: =D4 -> 0.047375862 | D5: ='Portfolio Details'!E6*'Portfolio Details'!E6*Correlation!D4 -> 0.1120814 | E5: ='Portfolio Details'!E6*'Portfolio Details'!E7*Correlation!F4 -> 3.8697557e-05 | F5: ='Portfolio Details'!E6*'Portfolio Details'!E8*Correlation!G4 -> 0.0076917727 | G5: ='Portfolio Details'!E6*'Portfolio Details'!E9*Correlation!K4 -> 0.021493616 | H5: ='Portfolio Details'!E6*'Portfolio Details'!E10*Correlation!L4 -> 0.00064070413 | I5: ='Portfolio Details'!E6*'Portfolio Details'!E11*Correlation!H4 -> 0.0076769886 | J5: ='Portfolio Details'!E5*'Portfolio Details'!E12*Correlation!I4 -> 0.0022562315
B6: Giltbees | C6: =E4 -> 0.00010794321 | D6: =E5 -> 3.8697557e-05 | E6: ='Portfolio Details'!E7*'Portfolio Details'!E7*Correlation!F6 -> 0.0020286024 | F6: ='Portfolio Details'!E7*'Portfolio Details'!E8*Correlation!G6 -> 0.00012881658 | G6: ='Portfolio Details'!E7*'Portfolio Details'!E9*Correlation!K6 -> 0.00081440529 | H6: ='Portfolio Details'!E7*'Portfolio Details'!E10*Correlation!L6 -> -0.00030788484 | I6: ='Portfolio Details'!E7*'Portfolio Details'!E11*Correlation!H6 -> -7.9698099e-05 | J6: ='Portfolio Details'!E7*'Portfolio Details'!E12*Correlation!I6 -> 7.6214306e-05
B7: Bankbees | C7: =F4 -> 0.0015448321 | D7: =F5 -> 0.0076917727 | E7: =F6 -> 0.00012881658 | F7: ='Portfolio Details'!E8*'Portfolio Details'!E8*Correlation!G7 -> 0.024758151 | G7: ='Portfolio Details'!E8*'Portfolio Details'!E9*Correlation!K7 -> 0.0075134905 | H7: ='Portfolio Details'!E8*'Portfolio Details'!E10*Correlation!L7 -> 0.00015217451 | I7: ='Portfolio Details'!E8*'Portfolio Details'!E11*Correlation!H7 -> 0.011267829 | J7: ='Portfolio Details'!E8*'Portfolio Details'!E12*Correlation!I7 -> 0.0085058535
B8: Hangseng | C8: =G4 -> 0.007198534 | D8: =G5 -> 0.021493616 | E8: =G6 -> 0.00081440529 | F8: =G7 -> 0.0075134905 | G8: ='Portfolio Details'!E9*'Portfolio Details'!E9*Correlation!K11 -> 0.07006614 | H8: ='Portfolio Details'!E9*'Portfolio Details'!E10*Correlation!L11 -> 0.00018230926 | I8: ='Portfolio Details'!E9*'Portfolio Details'!E11*Correlation!H11 -> 0.0082279024 | J8: ='Portfolio Details'!E9*'Portfolio Details'!E12*Correlation!I11 -> 0.0044303339
B9: Nasdaq | C9: =H4 -> 0.0032900677 | D9: =H5 -> 0.00064070413 | E9: =H6 -> -0.00030788484 | F9: =H7 -> 0.00015217451 | G9: =H8 -> 0.00018230926 | H9: ='Portfolio Details'!E10*'Portfolio Details'!E10*Correlation!L12 -> 0.043346722 | I9: ='Portfolio Details'!E10*'Portfolio Details'!E11*Correlation!H12 -> 0.0017350803 | J9: ='Portfolio Details'!E10*'Portfolio Details'!E12*Correlation!I12 -> 0.0011668774
B10: Itbees | C10: =I4 -> 0.00050359514 | D10: =I5 -> 0.0076769886 | E10: =I6 -> -7.9698099e-05 | F10: =I7 -> 0.011267829 | G10: =I8 -> 0.0082279024 | H10: =I9 -> 0.0017350803 | I10: ='Portfolio Details'!E11*'Portfolio Details'!E11*1 -> 0.042281993 | J10: ='Portfolio Details'!E11*'Portfolio Details'!E12*Correlation!I8 -> 0.01076419
B11: Healthy | C11: =J4 -> 0.00070312324 | D11: =J5 -> 0.0022562315 | E11: =J6 -> 7.6214306e-05 | F11: =J7 -> 0.0085058535 | G11: =J8 -> 0.0044303339 | H11: =J9 -> 0.0011668774 | I11: =J10 -> 0.01076419 | J11: ='Portfolio Details'!E12*'Portfolio Details'!E12*Correlation!I9 -> 0.020943469
I15: {=SQRT(SUM(MMULT(MMULT(TRANSPOSE('Portfolio Details'!D5:D12),Covariance!C4:J11),'Portfolio Details'!D5:D12)))} -> 0.099778246

Sheet Goldbees
B1: Symbol | C1: Date | D1: Prev Close | E1: Close Price | F1: Average Price | H1: Daily Returns% | I1: Weighted Returns | J1: Rolling Returns | K1: Weighted Rolling Returns
B2: GOLDBEES | C2: 44341 | D2: 42.2 | E2: 42.12 | F2: 42.14 | H2: =E2/D2-1 -> -0.0018957346 | I2: =H2*'Portfolio Details'!$D$5 -> -0.00037914692 | L2: Average daily return % | M2: =AVERAGE(H2:H1242) -> 0.00097198184
B3: GOLDBEES | C3: 44342 | D3: 42.12 | E3: 42.64 | F3: 42.56 | H3: =E3/D3-1 -> 0.012345679 | I3: =H3*'Portfolio Details'!$D$5 -> 0.0024691358
B4: GOLDBEES | C4: 44343 | D4: 42.64 | E4: 42.39 | F4: 42.44 | H4: =E4/D4-1 -> -0.0058630394 | I4: =H4*'Portfolio Details'!$D$5 -> -0.0011726079 | L4: Average Monthly return % | M4: =M2*20 -> 0.019439637
B5: GOLDBEES | C5: 44344 | D5: 42.39 | E5: 42.22 | F5: 42.2 | H5: =E5/D5-1 -> -0.0040103798 | I5: =H5*'Portfolio Details'!$D$5 -> -0.00080207596
B6: GOLDBEES | C6: 44347 | D6: 42.22 | E6: 42.59 | F6: 42.49 | H6: =E6/D6-1 -> 0.0087636191 | I6: =H6*'Portfolio Details'!$D$5 -> 0.0017527238 | L6: Average annual return % | M6: =M2*252 -> 0.24493942
B7: GOLDBEES | C7: 44348 | D7: 42.59 | E7: 42.83 | F7: 42.82 | H7: =E7/D7-1 -> 0.0056351256 | I7: =H7*'Portfolio Details'!$D$5 -> 0.0011270251
B8: GOLDBEES | C8: 44349 | D8: 42.83 | E8: 42.57 | F8: 42.65 | H8: =E8/D8-1 -> -0.0060705113 | I8: =H8*'Portfolio Details'!$D$5 -> -0.0012141023 | L8: CAGR% | M8: =(1+(E1242/E2-1))^(1/5)-1 -> 0.25380814
B9: GOLDBEES | C9: 44350 | D9: 42.57 | E9: 42.51 | F9: 42.63 | H9: =E9/D9-1 -> -0.0014094433 | I9: =H9*'Portfolio Details'!$D$5 -> -0.00028188865
B10: GOLDBEES | C10: 44351 | D10: 42.51 | E10: 42.12 | F10: 42.07 | H10: =E10/D10-1 -> -0.0091743119 | I10: =H10*'Portfolio Details'!$D$5 -> -0.0018348624 | L10: Risk | M10: =_xlfn.STDEV.P(H2:H1242) -> 0.011085896
B11: GOLDBEES | C11: 44354 | D11: 42.12 | E11: 42.28 | F11: 42.26 | H11: =E11/D11-1 -> 0.0037986705 | I11: =H11*'Portfolio Details'!$D$5 -> 0.00075973409
B12: GOLDBEES | C12: 44355 | D12: 42.28 | E12: 42.41 | F12: 42.51 | H12: =E12/D12-1 -> 0.0030747398 | I12: =H12*'Portfolio Details'!$D$5 -> 0.00061494797
B13: GOLDBEES | C13: 44356 | D13: 42.41 | E13: 42.5 | F13: 42.49 | H13: =E13/D13-1 -> 0.002122141 | I13: =H13*'Portfolio Details'!$D$5 -> 0.0004244282
B14: GOLDBEES | C14: 44357 | D14: 42.5 | E14: 42.35 | F14: 42.37 | H14: =E14/D14-1 -> -0.0035294118 | I14: =H14*'Portfolio Details'!$D$5 -> -0.00070588235
B15: GOLDBEES | C15: 44358 | D15: 42.35 | E15: 42.63 | F15: 42.67 | H15: =E15/D15-1 -> 0.0066115702 | I15: =H15*'Portfolio Details'!$D$5 -> 0.001322314 | L15: =0.13^2 -> 0.0169
B16: GOLDBEES | C16: 44361 | D16: 42.63 | E16: 42.03 | F16: 42.05 | H16: =E16/D16-1 -> -0.014074595 | I16: =H16*'Portfolio Details'!$D$5 -> -0.0028149191
B17: GOLDBEES | C17: 44362 | D17: 42.03 | E17: 42.05 | F17: 42.05 | H17: =E17/D17-1 -> 0.00047585058 | I17: =H17*'Portfolio Details'!$D$5 -> 9.5170117e-05
B18: GOLDBEES | C18: 44363 | D18: 42.05 | E18: 42.09 | F18: 42.05 | H18: =E18/D18-1 -> 0.00095124851 | I18: =H18*'Portfolio Details'!$D$5 -> 0.0001902497
B19: GOLDBEES | C19: 44364 | D19: 42.09 | E19: 41.35 | F19: 41.38 | H19: =E19/D19-1 -> -0.017581373 | I19: =H19*'Portfolio Details'!$D$5 -> -0.0035162746
B20: GOLDBEES | C20: 44365 | D20: 41.35 | E20: 40.96 | F20: 40.95 | H20: =E20/D20-1 -> -0.0094316808 | I20: =H20*'Portfolio Details'!$D$5 -> -0.0018863362
B21: GOLDBEES | C21: 44368 | D21: 40.96 | E21: 40.95 | F21: 40.79 | H21: =E21/D21-1 -> -0.00024414062 | I21: =H21*'Portfolio Details'!$D$5 -> -4.8828125e-05
B22: GOLDBEES | C22: 44369 | D22: 40.95 | E22: 40.93 | F22: 40.93 | H22: =E22/D22-1 -> -0.00048840049 | I22: =H22*'Portfolio Details'!$D$5 -> -9.7680098e-05
B23: GOLDBEES | C23: 44370 | D23: 40.93 | E23: 41 | F23: 40.96 | H23: =E23/D23-1 -> 0.001710237 | I23: =H23*'Portfolio Details'!$D$5 -> 0.0003420474
B24: GOLDBEES | C24: 44371 | D24: 41 | E24: 40.9 | F24: 40.85 | H24: =E24/D24-1 -> -0.0024390244 | I24: =H24*'Portfolio Details'!$D$5 -> -0.00048780488
B25: GOLDBEES | C25: 44372 | D25: 40.9 | E25: 40.95 | F25: 40.88 | H25: =E25/D25-1 -> 0.0012224939 | I25: =H25*'Portfolio Details'!$D$5 -> 0.00024449878 | J25: =(INDEX(E2:E1500,MATCH(EDATE(C2,1),C2:C1500,1))/E2)-1 -> -0.027777778 | K25: =J25*'Portfolio Details'!$D$5 -> -0.0055555556
B26: GOLDBEES | C26: 44375 | D26: 40.95 | E26: 40.82 | F26: 40.93 | H26: =E26/D26-1 -> -0.0031746032 | I26: =H26*'Portfolio Details'!$D$5 -> -0.00063492063 | J26: =(INDEX(E3:E1501,MATCH(EDATE(C3,1),C3:C1501,1))/E3)-1 -> -0.039634146 | K26: =J26*'Portfolio Details'!$D$5 -> -0.0079268293
B27: GOLDBEES | C27: 44376 | D27: 40.82 | E27: 40.73 | F27: 40.79 | H27: =E27/D27-1 -> -0.0022048016 | I27: =H27*'Portfolio Details'!$D$5 -> -0.00044096031 | J27: =(INDEX(E4:E1502,MATCH(EDATE(C4,1),C4:C1502,1))/E4)-1 -> -0.033970276 | K27: =J27*'Portfolio Details'!$D$5 -> -0.0067940552
B28: GOLDBEES | C28: 44377 | D28: 40.73 | E28: 40.52 | F28: 40.51 | H28: =E28/D28-1 -> -0.0051559047 | I28: =H28*'Portfolio Details'!$D$5 -> -0.0010311809 | J28: =(INDEX(E5:E1503,MATCH(EDATE(C5,1),C5:C1503,1))/E5)-1 -> -0.03315964 | K28: =J28*'Portfolio Details'!$D$5 -> -0.006631928
B29: GOLDBEES | C29: 44378 | D29: 40.52 | E29: 40.91 | F29: 40.84 | H29: =E29/D29-1 -> 0.0096248766 | I29: =H29*'Portfolio Details'!$D$5 -> 0.0019249753 | J29: =(INDEX(E6:E1504,MATCH(EDATE(C6,1),C6:C1504,1))/E6)-1 -> -0.048602958 | K29: =J29*'Portfolio Details'!$D$5 -> -0.0097205917
B30: GOLDBEES | C30: 44379 | D30: 40.91 | E30: 41.15 | F30: 41.1 | H30: =E30/D30-1 -> 0.0058665363 | I30: =H30*'Portfolio Details'!$D$5 -> 0.0011733073 | J30: =(INDEX(E7:E1505,MATCH(EDATE(C7,1),C7:C1505,1))/E7)-1 -> -0.044828391 | K30: =J30*'Portfolio Details'!$D$5 -> -0.0089656783
B31: GOLDBEES | C31: 44382 | D31: 41.15 | E31: 41.2 | F31: 41.18 | H31: =E31/D31-1 -> 0.0012150668 | I31: =H31*'Portfolio Details'!$D$5 -> 0.00024301337 | J31: =(INDEX(E8:E1506,MATCH(EDATE(C8,1),C8:C1506,1))/E8)-1 -> -0.033356824 | K31: =J31*'Portfolio Details'!$D$5 -> -0.0066713648
B32: GOLDBEES | C32: 44383 | D32: 41.2 | E32: 41.61 | F32: 41.5 | H32: =E32/D32-1 -> 0.0099514563 | I32: =H32*'Portfolio Details'!$D$5 -> 0.0019902913 | J32: =(INDEX(E9:E1507,MATCH(EDATE(C9,1),C9:C1507,1))/E9)-1 -> -0.031992472 | K32: =J32*'Portfolio Details'!$D$5 -> -0.0063984945
B33: GOLDBEES | C33: 44384 | D33: 41.61 | E33: 41.72 | F33: 41.65 | H33: =E33/D33-1 -> 0.0026435953 | I33: =H33*'Portfolio Details'!$D$5 -> 0.00052871906 | J33: =(INDEX(E10:E1508,MATCH(EDATE(C10,1),C10:C1508,1))/E10)-1 -> -0.02302944 | K33: =J33*'Portfolio Details'!$D$5 -> -0.0046058879
B34: GOLDBEES | C34: 44385 | D34: 41.72 | E34: 41.74 | F34: 41.72 | H34: =E34/D34-1 -> 0.00047938639 | I34: =H34*'Portfolio Details'!$D$5 -> 9.5877277e-05 | J34: =(INDEX(E11:E1509,MATCH(EDATE(C11,1),C11:C1509,1))/E11)-1 -> -0.013245033 | K34: =J34*'Portfolio Details'!$D$5 -> -0.0026490066
B35: GOLDBEES | C35: 44386 | D35: 41.74 | E35: 41.58 | F35: 41.55 | H35: =E35/D35-1 -> -0.0038332535 | I35: =H35*'Portfolio Details'!$D$5 -> -0.00076665069 | J35: =(INDEX(E12:E1510,MATCH(EDATE(C12,1),C12:C1510,1))/E12)-1 -> -0.015798161 | K35: =J35*'Portfolio Details'!$D$5 -> -0.0031596322
B36: GOLDBEES | C36: 44389 | D36: 41.58 | E36: 41.5 | F36: 41.49 | H36: =E36/D36-1 -> -0.0019240019 | I36: =H36*'Portfolio Details'!$D$5 -> -0.00038480038 | J36: =(INDEX(E13:E1511,MATCH(EDATE(C13,1),C13:C1511,1))/E13)-1 -> -0.021647059 | K36: =J36*'Portfolio Details'!$D$5 -> -0.0043294118
... B1242: GOLDBEES | C1242: 46167 | D1242: 130.5 | E1242: 130.51 | F1242: 130.56 | H1242: =E1242/D1242-1 -> 7.6628352e-05 | I1242: =H1242*'Portfolio Details'!$D$5 -> 1.532567e-05 | J1242: =(INDEX(E1219:E2717,MATCH(EDATE(C1219,1),C1219:C2717,1))/E1219)-1 -> 0.044082415 | K1242: =J1242*'Portfolio Details'!$D$5 -> 0.008816483

Sheet Silverbees
B1: Symbol | C1: Date | D1: Prev Close | E1: Close Price | F1: Average Price | H1: Daily Returns% | I1: Weighted Returns | J1: Rolling Returns | K1: Weighted Rolling Returns
B2: NETFSILVER | C2: 44599 | D2: 61.27 | E2: 61.77 | F2: 62.19 | H2: =E2/D2-1 -> 0.0081606006 | I2: =H2*'Portfolio Details'!$D$6 -> 0.00040803003 | L2: Average daily return % | M2: =AVERAGE(H2:H1065) -> 0.001570769
B3: NETFSILVER | C3: 44600 | D3: 61.77 | E3: 62.28 | F3: 62.04 | H3: =E3/D3-1 -> 0.0082564352 | I3: =H3*'Portfolio Details'!$D$6 -> 0.00041282176
B4: NETFSILVER | C4: 44601 | D4: 62.28 | E4: 62.77 | F4: 62.77 | H4: =E4/D4-1 -> 0.0078676943 | I4: =H4*'Portfolio Details'!$D$6 -> 0.00039338471 | L4: Average Monthly return % | M4: =M2*20 -> 0.03141538
B5: NETFSILVER | C5: 44602 | D5: 62.77 | E5: 62.8 | F5: 62.74 | H5: =E5/D5-1 -> 0.00047793532 | I5: =H5*'Portfolio Details'!$D$6 -> 2.3896766e-05
B6: NETFSILVER | C6: 44603 | D6: 62.8 | E6: 62.36 | F6: 62.32 | H6: =E6/D6-1 -> -0.0070063694 | I6: =H6*'Portfolio Details'!$D$6 -> -0.00035031847 | L6: Average annual return % | M6: =M2*252 -> 0.39583379
B7: NETFSILVER | C7: 44606 | D7: 62.36 | E7: 64.09 | F7: 63.93 | H7: =E7/D7-1 -> 0.027742142 | I7: =H7*'Portfolio Details'!$D$6 -> 0.0013871071
B8: NETFSILVER | C8: 44607 | D8: 64.09 | E8: 63.19 | F8: 63.9 | H8: =E8/D8-1 -> -0.014042752 | I8: =H8*'Portfolio Details'!$D$6 -> -0.00070213762 | L8: CAGR% | M8: =(1+(E1065/E2-1))^(1/4.5)-1 -> 0.37159271
B9: NETFSILVER | C9: 44608 | D9: 63.19 | E9: 63.24 | F9: 63.07 | H9: =E9/D9-1 -> 0.00079126444 | I9: =H9*'Portfolio Details'!$D$6 -> 3.9563222e-05
B10: NETFSILVER | C10: 44609 | D10: 63.24 | E10: 63.87 | F10: 63.5 | H10: =E10/D10-1 -> 0.0099620493 | I10: =H10*'Portfolio Details'!$D$6 -> 0.00049810247 | L10: Risk | M10: =_xlfn.STDEV.P(H2:H1065) -> 0.021089511
B11: NETFSILVER | C11: 44610 | D11: 63.87 | E11: 63.79 | F11: 63.8 | H11: =E11/D11-1 -> -0.0012525442 | I11: =H11*'Portfolio Details'!$D$6 -> -6.2627212e-05
B12: NETFSILVER | C12: 44613 | D12: 63.79 | E12: 63.42 | F12: 63.4 | H12: =E12/D12-1 -> -0.0058002822 | I12: =H12*'Portfolio Details'!$D$6 -> -0.00029001411
B13: NETFSILVER | C13: 44614 | D13: 63.42 | E13: 64.29 | F13: 64.35 | H13: =E13/D13-1 -> 0.01371807 | I13: =H13*'Portfolio Details'!$D$6 -> 0.0006859035
B14: NETFSILVER | C14: 44615 | D14: 64.29 | E14: 64.08 | F14: 64.13 | H14: =E14/D14-1 -> -0.0032664489 | I14: =H14*'Portfolio Details'!$D$6 -> -0.00016332245
B15: NETFSILVER | C15: 44616 | D15: 64.08 | E15: 66.98 | F15: 66.55 | H15: =E15/D15-1 -> 0.04525593 | I15: =H15*'Portfolio Details'!$D$6 -> 0.0022627965
B16: NETFSILVER | C16: 44617 | D16: 66.98 | E16: 64.68 | F16: 64.86 | H16: =E16/D16-1 -> -0.034338609 | I16: =H16*'Portfolio Details'!$D$6 -> -0.0017169304
B17: NETFSILVER | C17: 44620 | D17: 64.68 | E17: 64.85 | F17: 65.06 | H17: =E17/D17-1 -> 0.0026283241 | I17: =H17*'Portfolio Details'!$D$6 -> 0.0001314162
B18: NETFSILVER | C18: 44622 | D18: 64.85 | E18: 67.09 | F18: 66.93 | H18: =E18/D18-1 -> 0.034541249 | I18: =H18*'Portfolio Details'!$D$6 -> 0.0017270625
B19: NETFSILVER | C19: 44623 | D19: 67.09 | E19: 67.48 | F19: 67.41 | H19: =E19/D19-1 -> 0.0058130869 | I19: =H19*'Portfolio Details'!$D$6 -> 0.00029065434
B20: NETFSILVER | C20: 44624 | D20: 67.48 | E20: 67.52 | F20: 67.44 | H20: =E20/D20-1 -> 0.00059276823 | I20: =H20*'Portfolio Details'!$D$6 -> 2.9638411e-05
B21: NETFSILVER | C21: 44627 | D21: 67.52 | E21: 70.37 | F21: 70.27 | H21: =E21/D21-1 -> 0.042209716 | I21: =H21*'Portfolio Details'!$D$6 -> 0.0021104858
B22: NETFSILVER | C22: 44628 | D22: 70.37 | E22: 70.56 | F22: 70.16 | H22: =E22/D22-1 -> 0.0027000142 | I22: =H22*'Portfolio Details'!$D$6 -> 0.00013500071
... B24: NETFSILVER | C24: 44630 | D24: 70.65 | E24: 68.5 | F24: 68.6 | H24: =E24/D24-1 -> -0.030431706 | I24: =H24*'Portfolio Details'!$D$6 -> -0.0015215853
B25: NETFSILVER | C25: 44631 | D25: 68.5 | E25: 69.47 | F25: 69.42 | H25: =E25/D25-1 -> 0.014160584 | I25: =H25*'Portfolio Details'!$D$6 -> 0.0007080292 | J25: =(INDEX(E2:E1500,MATCH(EDATE(C2,1),C2:C1500,1))/E2)-1 -> 0.13922616 | K25: =J25*'Portfolio Details'!$D$6 -> 0.0069613081
B26: NETFSILVER | C26: 44634 | D26: 69.47 | E26: 68.49 | F26: 68.75 | H26: =E26/D26-1 -> -0.014106809 | I26: =H26*'Portfolio Details'!$D$6 -> -0.00070534043 | J26: =(INDEX(E3:E1501,MATCH(EDATE(C3,1),C3:C1501,1))/E3)-1 -> 0.13294798 | K26: =J26*'Portfolio Details'!$D$6 -> 0.0066473988
B27: NETFSILVER | C27: 44635 | D27: 68.49 | E27: 66.96 | F27: 67.14 | H27: =E27/D27-1 -> -0.022339028 | I27: =H27*'Portfolio Details'!$D$6 -> -0.0011169514 | J27: =(INDEX(E4:E1502,MATCH(EDATE(C4,1),C4:C1502,1))/E4)-1 -> 0.12553768 | K27: =J27*'Portfolio Details'!$D$6 -> 0.0062768839
B28: NETFSILVER | C28: 44636 | D28: 66.96 | E28: 67.14 | F28: 67.04 | H28: =E28/D28-1 -> 0.002688172 | I28: =H28*'Portfolio Details'!$D$6 -> 0.0001344086 | J28: =(INDEX(E5:E1503,MATCH(EDATE(C5,1),C5:C1503,1))/E5)-1 -> 0.090764331 | K28: =J28*'Portfolio Details'!$D$6 -> 0.0045382166
B29: NETFSILVER | C29: 44637 | D29: 67.14 | E29: 67.55 | F29: 67.38 | H29: =E29/D29-1 -> 0.0061066428 | I29: =H29*'Portfolio Details'!$D$6 -> 0.00030533214 | J29: =(INDEX(E6:E1504,MATCH(EDATE(C6,1),C6:C1504,1))/E6)-1 -> 0.11401539 | K29: =J29*'Portfolio Details'!$D$6 -> 0.0057007697
B30: NETFSILVER | C30: 44641 | D30: 67.55 | E30: 67.35 | F30: 67.26 | H30: =E30/D30-1 -> -0.0029607698 | I30: =H30*'Portfolio Details'!$D$6 -> -0.00014803849 | J30: =(INDEX(E7:E1505,MATCH(EDATE(C7,1),C7:C1505,1))/E7)-1 -> 0.068653456 | K30: =J30*'Portfolio Details'!$D$6 -> 0.0034326728
B31: NETFSILVER | C31: 44642 | D31: 67.35 | E31: 67.47 | F31: 67.9 | H31: =E31/D31-1 -> 0.0017817372 | I31: =H31*'Portfolio Details'!$D$6 -> 8.908686e-05 | J31: =(INDEX(E8:E1506,MATCH(EDATE(C8,1),C8:C1506,1))/E8)-1 -> 0.059661339 | K31: =J31*'Portfolio Details'!$D$6 -> 0.0029830669
B32: NETFSILVER | C32: 44643 | D32: 67.47 | E32: 67.34 | F32: 66.9 | H32: =E32/D32-1 -> -0.0019267823 | I32: =H32*'Portfolio Details'!$D$6 -> -9.6339114e-05 | J32: =(INDEX(E9:E1507,MATCH(EDATE(C9,1),C9:C1507,1))/E9)-1 -> 0.061669829 | K32: =J32*'Portfolio Details'!$D$6 -> 0.0030834915
B33: NETFSILVER | C33: 44644 | D33: 67.34 | E33: 67.52 | F33: 67.49 | H33: =E33/D33-1 -> 0.0026730027 | I33: =H33*'Portfolio Details'!$D$6 -> 0.00013365013 | J33: =(INDEX(E10:E1508,MATCH(EDATE(C10,1),C10:C1508,1))/E10)-1 -> 0.057617035 | K33: =J33*'Portfolio Details'!$D$6 -> 0.0028808517
B34: NETFSILVER | C34: 44645 | D34: 67.52 | E34: 68.6 | F34: 68.5 | H34: =E34/D34-1 -> 0.015995261 | I34: =H34*'Portfolio Details'!$D$6 -> 0.00079976303 | J34: =(INDEX(E11:E1509,MATCH(EDATE(C11,1),C11:C1509,1))/E11)-1 -> 0.058943408 | K34: =J34*'Portfolio Details'!$D$6 -> 0.0029471704
B35: NETFSILVER | C35: 44648 | D35: 68.6 | E35: 67.35 | F35: 67.5 | H35: =E35/D35-1 -> -0.018221574 | I35: =H35*'Portfolio Details'!$D$6 -> -0.00091107872 | J35: =(INDEX(E12:E1510,MATCH(EDATE(C12,1),C12:C1510,1))/E12)-1 -> 0.061967833 | K35: =J35*'Portfolio Details'!$D$6 -> 0.0030983917
B36: NETFSILVER | C36: 44649 | D36: 67.35 | E36: 66.39 | F36: 66.66 | H36: =E36/D36-1 -> -0.014253898 | I36: =H36*'Portfolio Details'!$D$6 -> -0.00071269488 | J36: =(INDEX(E13:E1511,MATCH(EDATE(C13,1),C13:C1511,1))/E13)-1 -> 0.049463369 | K36: =J36*'Portfolio Details'!$D$6 -> 0.0024731685
... B1065: SILVERBEES | C1065: 46167 | D1065: 252.54 | E1065: 256.03 | F1065: 255.88 | H1065: =E1065/D1065-1 -> 0.013819593 | I1065: =H1065*'Portfolio Details'!$D$6 -> 0.00069097965 | J1065: =(INDEX(E1042:E2540,MATCH(EDATE(C1042,1),C1042:C2540,1))/E1042)-1 -> 0.061328503 | K1065: =J1065*'Portfolio Details'!$D$6 -> 0.0030664252
H1066: =E1066/D1066-1 -> #DIV/0! | I1066: =H1066*'Portfolio Details'!$D$6 -> #DIV/0! | J1066: =(INDEX(E1043:E2541,MATCH(EDATE(C1043,1),C1043:C2541,1))/E1043)-1 -> 0.069948735 | K1066: =J1066*'Portfolio Details'!$D$6 -> 0.0034974368
H1067: =E1067/D1067-1 -> #DIV/0! | I1067: =H1067*'Portfolio Details'!$D$6 -> #DIV/0! | J1067: =(INDEX(E1044:E2542,MATCH(EDATE(C1044,1),C1044:C2542,1))/E1044)-1 -> 0.099577655 | K1067: =J1067*'Portfolio Details'!$D$6 -> 0.0049788827
H1068: =E1068/D1068-1 -> #DIV/0! | I1068: =H1068*'Portfolio Details'!$D$6 -> #DIV/0! | J1068: =(INDEX(E1045:E2543,MATCH(EDATE(C1045,1),C1045:C2543,1))/E1045)-1 -> 0.10816622 | K1068: =J1068*'Portfolio Details'!$D$6 -> 0.005408311
H1069: =E1069/D1069-1 -> #DIV/0! | I1069: =H1069*'Portfolio Details'!$D$6 -> #DIV/0! | J1069: =(INDEX(E1046:E2544,MATCH(EDATE(C1046,1),C1046:C2544,1))/E1046)-1 -> 0.10970007 | K1069: =J1069*'Portfolio Details'!$D$6 -> 0.0054850035
...

Sheet Autobees
B1: Symbol | C1: Date | D1: Prev Close | E1: Close Price | F1: Average Price | H1: Daily Returns%
B2: NETFAUTO | C2: 44586 | D2: 115.94 | E2: 115.77 | F2: 114.99 | H2: =E2/D2-1 -> -0.0014662757 | O2: Average daily return % | P2: =AVERAGE(H2:H1073) -> 0.00086228236
B3: NETFAUTO | C3: 44588 | D3: 115.77 | E3: 114.37 | F3: 114.48 | H3: =E3/D3-1 -> -0.012092943
B4: NETFAUTO | C4: 44589 | D4: 114.37 | E4: 115.38 | F4: 116.98 | H4: =E4/D4-1 -> 0.0088309871 | O4: Average Monthly return % | P4: =P2*20 -> 0.017245647
B5: NETFAUTO | C5: 44592 | D5: 115.38 | E5: 117.42 | F5: 117.11 | H5: =E5/D5-1 -> 0.017680707
B6: NETFAUTO | C6: 44593 | D6: 117.42 | E6: 116.64 | F6: 117.27 | H6: =E6/D6-1 -> -0.0066428206 | O6: Average annual return % | P6: =P2*252 -> 0.21729515
B7: NETFAUTO | C7: 44594 | D7: 116.64 | E7: 116.83 | F7: 117.37 | H7: =E7/D7-1 -> 0.0016289438
B8: NETFAUTO | C8: 44595 | D8: 116.83 | E8: 117.43 | F8: 117.76 | H8: =E8/D8-1 -> 0.0051356672 | O8: CAGR% | P8: =(1+(E1073/E2-1))^(1/5)-1 -> 0.18581998
B9: NETFAUTO | C9: 44596 | D9: 117.43 | E9: 115.94 | F9: 116.51 | H9: =E9/D9-1 -> -0.01268841
B10: NETFAUTO | C10: 44599 | D10: 115.94 | E10: 114.42 | F10: 114.79 | H10: =E10/D10-1 -> -0.013110229 | O10: Risk | P10: =_xlfn.STDEV.P(H2:H1073) -> 0.011694926
B11: NETFAUTO | C11: 44600 | D11: 114.42 | E11: 114.15 | F11: 114.64 | H11: =E11/D11-1 -> -0.0023597273
B12: NETFAUTO | C12: 44601 | D12: 114.15 | E12: 116.56 | F12: 115.97 | H12: =E12/D12-1 -> 0.021112571
B13: NETFAUTO | C13: 44602 | D13: 116.56 | E13: 116.98 | F13: 117.52 | H13: =E13/D13-1 -> 0.0036032944
B14: NETFAUTO | C14: 44603 | D14: 116.98 | E14: 115.84 | F14: 115.93 | H14: =E14/D14-1 -> -0.0097452556
B15: NETFAUTO | C15: 44606 | D15: 115.84 | E15: 111.26 | F15: 112.72 | H15: =E15/D15-1 -> -0.039537293
B16: NETFAUTO | C16: 44607 | D16: 111.26 | E16: 115.14 | F16: 113.26 | H16: =E16/D16-1 -> 0.03487327
B17: NETFAUTO | C17: 44608 | D17: 115.14 | E17: 115.29 | F17: 115.65 | H17: =E17/D17-1 -> 0.0013027619
B18: NETFAUTO | C18: 44609 | D18: 115.29 | E18: 115.18 | F18: 115.6 | H18: =E18/D18-1 -> -0.00095411571
B19: NETFAUTO | C19: 44610 | D19: 115.18 | E19: 114.54 | F19: 114.83 | H19: =E19/D19-1 -> -0.0055565202
B20: NETFAUTO | C20: 44613 | D20: 114.54 | E20: 114.13 | F20: 113.62 | H20: =E20/D20-1 -> -0.0035795355
B21: NETFAUTO | C21: 44614 | D21: 114.13 | E21: 114.12 | F21: 114.9 | H21: =E21/D21-1 -> -8.7619381e-05
B22: NETFAUTO | C22: 44615 | D22: 114.12 | E22: 113.69 | F22: 114.26 | H22: =E22/D22-1 -> -0.0037679635
... B1073: AUTOBEES | C1073: 46167 | D1073: 267.12 | E1073: 271.45 | F1073: 271.94 | H1073: =E1073/D1073-1 -> 0.016209943

Sheet Giltbees
B1: Symbol | C1: Date | D1: Prev Close | E1: Close Price | F1: Average Price | H1: Daily Returns% | I1: Weighted Returns | J1: Rolling Returns | K1: Weighted Rolling Returns
B2: NETFGILT5Y | C2: 44341 | D2: 48.3 | E2: 48.4 | F2: 48.32 | H2: =E2/D2-1 -> 0.0020703934 | I2: =H2*'Portfolio Details'!$D$7 -> 0.00010351967 | L2: Average daily return % | M2: =AVERAGE(H2:H1239) -> 0.00023465857
B3: NETFGILT5Y | C3: 44342 | D3: 48.4 | E3: 48.44 | F3: 48.44 | H3: =E3/D3-1 -> 0.00082644628 | I3: =H3*'Portfolio Details'!$D$7 -> 4.1322314e-05
B4: NETFGILT5Y | C4: 44343 | D4: 48.44 | E4: 48.38 | F4: 48.39 | H4: =E4/D4-1 -> -0.0012386457 | I4: =H4*'Portfolio Details'!$D$7 -> -6.1932287e-05 | L4: Average Monthly return % | M4: =M2*20 -> 0.0046931713
B5: NETFGILT5Y | C5: 44344 | D5: 48.38 | E5: 48.34 | F5: 48.36 | H5: =E5/D5-1 -> -0.00082678793 | I5: =H5*'Portfolio Details'!$D$7 -> -4.1339396e-05
B6: NETFGILT5Y | C6: 44347 | D6: 48.34 | E6: 48.32 | F6: 48.34 | H6: =E6/D6-1 -> -0.00041373604 | I6: =H6*'Portfolio Details'!$D$7 -> -2.0686802e-05 | L6: Average annual return % | M6: =M2*252 -> 0.059133958
B7: NETFGILT5Y | C7: 44348 | D7: 48.32 | E7: 48.3 | F7: 48.33 | H7: =E7/D7-1 -> -0.00041390728 | I7: =H7*'Portfolio Details'!$D$7 -> -2.0695364e-05
B8: NETFGILT5Y | C8: 44349 | D8: 48.3 | E8: 48.3 | F8: 48.3 | H8: =E8/D8-1 -> 0 | I8: =H8*'Portfolio Details'!$D$7 -> 0 | L8: CAGR% | M8: =(1+(E1239/E2-1))^(1/5)-1 -> 0.058325041
B9: NETFGILT5Y | C9: 44350 | D9: 48.3 | E9: 48.34 | F9: 48.33 | H9: =E9/D9-1 -> 0.00082815735 | I9: =H9*'Portfolio Details'!$D$7 -> 4.1407867e-05
B10: NETFGILT5Y | C10: 44351 | D10: 48.34 | E10: 48.38 | F10: 48.4 | H10: =E10/D10-1 -> 0.00082747207 | I10: =H10*'Portfolio Details'!$D$7 -> 4.1373604e-05 | L10: Risk | M10: =_xlfn.STDEV.P(H2:H1239) -> 0.0028372539
B11: NETFGILT5Y | C11: 44354 | D11: 48.38 | E11: 48.38 | F11: 48.38 | H11: =E11/D11-1 -> 0 | I11: =H11*'Portfolio Details'!$D$7 -> 0
B12: NETFGILT5Y | C12: 44355 | D12: 48.38 | E12: 48.47 | F12: 48.44 | H12: =E12/D12-1 -> 0.0018602728 | I12: =H12*'Portfolio Details'!$D$7 -> 9.3013642e-05
B13: NETFGILT5Y | C13: 44356 | D13: 48.47 | E13: 48.48 | F13: 48.51 | H13: =E13/D13-1 -> 0.00020631318 | I13: =H13*'Portfolio Details'!$D$7 -> 1.0315659e-05
B14: NETFGILT5Y | C14: 44357 | D14: 48.48 | E14: 48.52 | F14: 48.55 | H14: =E14/D14-1 -> 0.00082508251 | I14: =H14*'Portfolio Details'!$D$7 -> 4.1254125e-05
B15: NETFGILT5Y | C15: 44358 | D15: 48.52 | E15: 48.63 | F15: 48.53 | H15: =E15/D15-1 -> 0.0022671063 | I15: =H15*'Portfolio Details'!$D$7 -> 0.00011335532
B16: NETFGILT5Y | C16: 44361 | D16: 48.63 | E16: 48.61 | F16: 48.61 | H16: =E16/D16-1 -> -0.00041126876 | I16: =H16*'Portfolio Details'!$D$7 -> -2.0563438e-05
B17: NETFGILT5Y | C17: 44362 | D17: 48.61 | E17: 48.42 | F17: 48.42 | H17: =E17/D17-1 -> -0.0039086608 | I17: =H17*'Portfolio Details'!$D$7 -> -0.00019543304
B18: NETFGILT5Y | C18: 44363 | D18: 48.42 | E18: 48.23 | F18: 48.22 | H18: =E18/D18-1 -> -0.0039239983 | I18: =H18*'Portfolio Details'!$D$7 -> -0.00019619992
B19: NETFGILT5Y | C19: 44365 | D19: 48.23 | E19: 48.33 | F19: 48.33 | H19: =E19/D19-1 -> 0.0020733983 | I19: =H19*'Portfolio Details'!$D$7 -> 0.00010366991
B20: NETFGILT5Y | C20: 44368 | D20: 48.33 | E20: 48.31 | F20: 48.36 | H20: =E20/D20-1 -> -0.00041382164 | I20: =H20*'Portfolio Details'!$D$7 -> -2.0691082e-05
B21: NETFGILT5Y | C21: 44369 | D21: 48.31 | E21: 48.21 | F21: 48.22 | H21: =E21/D21-1 -> -0.0020699648 | I21: =H21*'Portfolio Details'!$D$7 -> -0.00010349824
B22: NETFGILT5Y | C22: 44370 | D22: 48.21 | E22: 48.23 | F22: 48.22 | H22: =E22/D22-1 -> 0.00041485169 | I22: =H22*'Portfolio Details'!$D$7 -> 2.0742585e-05
... B24: NETFGILT5Y | C24: 44372 | D24: 48.26 | E24: 48.19 | F24: 48.16 | H24: =E24/D24-1 -> -0.0014504766 | I24: =H24*'Portfolio Details'!$D$7 -> -7.2523829e-05
B25: NETFGILT5Y | C25: 44375 | D25: 48.19 | E25: 48.12 | F25: 48.17 | H25: =E25/D25-1 -> -0.0014525835 | I25: =H25*'Portfolio Details'!$D$7 -> -7.2629176e-05 | J25: =(INDEX(E2:E1500,MATCH(EDATE(C2,1),C2:C1500,1))/E2)-1 -> -0.004338843
B26: NETFGILT5Y | C26: 44376 | D26: 48.12 | E26: 48.18 | F26: 48.18 | H26: =E26/D26-1 -> 0.0012468828 | I26: =H26*'Portfolio Details'!$D$7 -> 6.234414e-05 | J26: =(INDEX(E3:E1501,MATCH(EDATE(C3,1),C3:C1501,1))/E3)-1 -> -0.0051610239
B27: NETFGILT5Y | C27: 44377 | D27: 48.18 | E27: 48.1 | F27: 48.1 | H27: =E27/D27-1 -> -0.00166044 | I27: =H27*'Portfolio Details'!$D$7 -> -8.3022001e-05 | J27: =(INDEX(E4:E1502,MATCH(EDATE(C4,1),C4:C1502,1))/E4)-1 -> -0.0039272427
B28: NETFGILT5Y | C28: 44378 | D28: 48.1 | E28: 48.14 | F28: 48.19 | H28: =E28/D28-1 -> 0.00083160083 | I28: =H28*'Portfolio Details'!$D$7 -> 4.1580042e-05 | J28: =(INDEX(E5:E1503,MATCH(EDATE(C5,1),C5:C1503,1))/E5)-1 -> -0.0045510964
B29: NETFGILT5Y | C29: 44379 | D29: 48.14 | E29: 48.15 | F29: 48.2 | H29: =E29/D29-1 -> 0.00020772746 | I29: =H29*'Portfolio Details'!$D$7 -> 1.0386373e-05 | J29: =(INDEX(E6:E1504,MATCH(EDATE(C6,1),C6:C1504,1))/E6)-1 -> -0.0045529801
B30: NETFGILT5Y | C30: 44382 | D30: 48.15 | E30: 48.12 | F30: 48.1 | H30: =E30/D30-1 -> -0.00062305296 | I30: =H30*'Portfolio Details'!$D$7 -> -3.1152648e-05 | J30: =(INDEX(E7:E1505,MATCH(EDATE(C7,1),C7:C1505,1))/E7)-1 -> -0.0033126294
B31: NETFGILT5Y | C31: 44383 | D31: 48.12 | E31: 47.93 | F31: 47.97 | H31: =E31/D31-1 -> -0.0039484622 | I31: =H31*'Portfolio Details'!$D$7 -> -0.00019742311 | J31: =(INDEX(E8:E1506,MATCH(EDATE(C8,1),C8:C1506,1))/E8)-1 -> -0.0031055901
B32: NETFGILT5Y | C32: 44384 | D32: 47.93 | E32: 48.01 | F32: 47.97 | H32: =E32/D32-1 -> 0.0016691008 | I32: =H32*'Portfolio Details'!$D$7 -> 8.3455039e-05 | J32: =(INDEX(E9:E1507,MATCH(EDATE(C9,1),C9:C1507,1))/E9)-1 -> -0.0039304923
B33: NETFGILT5Y | C33: 44385 | D33: 48.01 | E33: 48.15 | F33: 48.06 | H33: =E33/D33-1 -> 0.0029160592 | I33: =H33*'Portfolio Details'!$D$7 -> 0.00014580296 | J33: =(INDEX(E10:E1508,MATCH(EDATE(C10,1),C10:C1508,1))/E10)-1 -> -0.0047540306
B34: NETFGILT5Y | C34: 44386 | D34: 48.15 | E34: 48.2 | F34: 48.19 | H34: =E34/D34-1 -> 0.0010384216 | I34: =H34*'Portfolio Details'!$D$7 -> 5.192108e-05 | J34: =(INDEX(E11:E1509,MATCH(EDATE(C11,1),C11:C1509,1))/E11)-1 -> -0.0076477883
B35: NETFGILT5Y | C35: 44389 | D35: 48.2 | E35: 48.21 | F35: 48.22 | H35: =E35/D35-1 -> 0.00020746888 | I35: =H35*'Portfolio Details'!$D$7 -> 1.0373444e-05 | J35: =(INDEX(E12:E1510,MATCH(EDATE(C12,1),C12:C1510,1))/E12)-1 -> -0.0066020219
B36: NETFGILT5Y | C36: 44390 | D36: 48.21 | E36: 48.19 | F36: 48.2 | H36: =E36/D36-1 -> -0.00041485169 | I36: =H36*'Portfolio Details'!$D$7 -> -2.0742585e-05 | J36: =(INDEX(E13:E1511,MATCH(EDATE(C13,1),C13:C1511,1))/E13)-1 -> -0.0057755776
... B1239: GILT5YBEES | C1239: 46167 | D1239: 64.07 | E1239: 64.26 | F1239: 64.19 | H1239: =E1239/D1239-1 -> 0.0029655065 | I1239: =H1239*'Portfolio Details'!$D$7 -> 0.00014827532 | J1239: =(INDEX(E1216:E2714,MATCH(EDATE(C1216,1),C1216:C2714,1))/E1216)-1 -> -0.010498688
J1240: =(INDEX(E1217:E2715,MATCH(EDATE(C1217,1),C1217:C2715,1))/E1217)-1 -> -0.010043263
J1241: =(INDEX(E1218:E2716,MATCH(EDATE(C1218,1),C1218:C2716,1))/E1218)-1 -> -0.0075898389
J1242: =(INDEX(E1219:E2717,MATCH(EDATE(C1219,1),C1219:C2717,1))/E1219)-1 -> -0.0078971818

Sheet Bankbees
B1: Symbol | C1: Date | D1: Prev Close | E1: Close Price | F1: Average Price | H1: Daily Returns% | I1: Weighted Returns | J1: Rolling Returns | K1: Weighted Rolling Returns
B2: BANKBEES | C2: 44341 | D2: 350.8 | E2: 348.59 | F2: 348.64 | H2: =E2/D2-1 -> -0.006299886 | I2: =H2*'Portfolio Details'!$D$8 -> -0.0012599772 | L2: Average daily return % | M2: =AVERAGE(H2:H1242) -> 0.00044182858
B3: BANKBEES | C3: 44342 | D3: 348.59 | E3: 348.9 | F3: 349.25 | H3: =E3/D3-1 -> 0.00088929688 | I3: =H3*'Portfolio Details'!$D$8 -> 0.00017785938
B4: BANKBEES | C4: 44343 | D4: 348.9 | E4: 352.59 | F4: 350.4 | H4: =E4/D4-1 -> 0.010576096 | I4: =H4*'Portfolio Details'!$D$8 -> 0.0021152193 | L4: Average Monthly return % | M4: =M2*20 -> 0.0088365717
B5: BANKBEES | C5: 44344 | D5: 352.59 | E5: 353.6 | F5: 354.11 | H5: =E5/D5-1 -> 0.0028645169 | I5: =H5*'Portfolio Details'!$D$8 -> 0.00057290337
B6: BANKBEES | C6: 44347 | D6: 353.6 | E6: 356.12 | F6: 354.85 | H6: =E6/D6-1 -> 0.0071266968 | I6: =H6*'Portfolio Details'!$D$8 -> 0.0014253394 | L6: Average annual return % | M6: =M2*252 -> 0.1113408
B7: BANKBEES | C7: 44348 | D7: 356.12 | E7: 355.47 | F7: 356.03 | H7: =E7/D7-1 -> -0.0018252275 | I7: =H7*'Portfolio Details'!$D$8 -> -0.00036504549
B8: BANKBEES | C8: 44349 | D8: 355.47 | E8: 355.63 | F8: 354.18 | H8: =E8/D8-1 -> 0.00045010831 | I8: =H8*'Portfolio Details'!$D$8 -> 9.0021661e-05 | L8: CAGR% | M8: =(1+(E1242/E2-1))^(1/5)-1 -> 0.10374126
B9: BANKBEES | C9: 44350 | D9: 355.63 | E9: 357.92 | F9: 357.61 | H9: =E9/D9-1 -> 0.0064392768 | I9: =H9*'Portfolio Details'!$D$8 -> 0.0012878554
B10: BANKBEES | C10: 44351 | D10: 357.92 | E10: 354.71 | F10: 356.06 | H10: =E10/D10-1 -> -0.0089684846 | I10: =H10*'Portfolio Details'!$D$8 -> -0.0017936969 | L10: Risk | M10: =_xlfn.STDEV.P(H2:H1242) -> 0.0099119438
B11: BANKBEES | C11: 44354 | D11: 354.71 | E11: 356.02 | F11: 356.27 | H11: =E11/D11-1 -> 0.0036931578 | I11: =H11*'Portfolio Details'!$D$8 -> 0.00073863156
B12: BANKBEES | C12: 44355 | D12: 356.02 | E12: 352.13 | F12: 352.16 | H12: =E12/D12-1 -> -0.010926352 | I12: =H12*'Portfolio Details'!$D$8 -> -0.0021852705
B13: BANKBEES | C13: 44356 | D13: 352.13 | E13: 349.43 | F13: 351.25 | H13: =E13/D13-1 -> -0.0076676228 | I13: =H13*'Portfolio Details'!$D$8 -> -0.0015335246
B14: BANKBEES | C14: 44357 | D14: 349.43 | E14: 352.63 | F14: 350.77 | H14: =E14/D14-1 -> 0.0091577712 | I14: =H14*'Portfolio Details'!$D$8 -> 0.0018315542
B15: BANKBEES | C15: 44358 | D15: 352.63 | E15: 351.59 | F15: 352.13 | H15: =E15/D15-1 -> -0.0029492669 | I15: =H15*'Portfolio Details'!$D$8 -> -0.00058985339
B16: BANKBEES | C16: 44361 | D16: 351.59 | E16: 350.78 | F16: 348.28 | H16: =E16/D16-1 -> -0.0023038198 | I16: =H16*'Portfolio Details'!$D$8 -> -0.00046076396
B17: BANKBEES | C17: 44362 | D17: 350.78 | E17: 353.59 | F17: 353.21 | H17: =E17/D17-1 -> 0.008010719 | I17: =H17*'Portfolio Details'!$D$8 -> 0.0016021438
B18: BANKBEES | C18: 44363 | D18: 353.59 | E18: 351.31 | F18: 352.24 | H18: =E18/D18-1 -> -0.0064481462 | I18: =H18*'Portfolio Details'!$D$8 -> -0.0012896292
B19: BANKBEES | C19: 44364 | D19: 351.31 | E19: 347.23 | F19: 347.78 | H19: =E19/D19-1 -> -0.011613675 | I19: =H19*'Portfolio Details'!$D$8 -> -0.0023227349
B20: BANKBEES | C20: 44365 | D20: 347.23 | E20: 347.08 | F20: 344.49 | H20: =E20/D20-1 -> -0.00043199032 | I20: =H20*'Portfolio Details'!$D$8 -> -8.6398065e-05
B21: BANKBEES | C21: 44368 | D21: 347.08 | E21: 350.13 | F21: 346.38 | H21: =E21/D21-1 -> 0.0087875994 | I21: =H21*'Portfolio Details'!$D$8 -> 0.0017575199
B22: BANKBEES | C22: 44369 | D22: 350.13 | E22: 349.04 | F22: 351.59 | H22: =E22/D22-1 -> -0.0031131294 | I22: =H22*'Portfolio Details'!$D$8 -> -0.00062262588
... B24: BANKBEES | C24: 44371 | D24: 347.84 | E24: 350.42 | F24: 350.01 | H24: =E24/D24-1 -> 0.0074172033 | I24: =H24*'Portfolio Details'!$D$8 -> 0.0014834407
B25: BANKBEES | C25: 44372 | D25: 350.42 | E25: 354.99 | F25: 354.3 | H25: =E25/D25-1 -> 0.013041493 | I25: =H25*'Portfolio Details'!$D$8 -> 0.0026082986 | J25: =(INDEX(E2:E1500,MATCH(EDATE(C2,1),C2:C1500,1))/E2)-1 -> 0.018359678 | K25: =J25*'Portfolio Details'!$D$8 -> 0.0036719355
B26: BANKBEES | C26: 44375 | D26: 354.99 | E26: 355.24 | F26: 355.23 | H26: =E26/D26-1 -> 0.00070424519 | I26: =H26*'Portfolio Details'!$D$8 -> 0.00014084904 | J26: =(INDEX(E3:E1501,MATCH(EDATE(C3,1),C3:C1501,1))/E3)-1 -> 0.017454858 | K26: =J26*'Portfolio Details'!$D$8 -> 0.0034909716
B27: BANKBEES | C27: 44376 | D27: 355.24 | E27: 352.73 | F27: 353.01 | H27: =E27/D27-1 -> -0.0070656458 | I27: =H27*'Portfolio Details'!$D$8 -> -0.0014131292 | J27: =(INDEX(E4:E1502,MATCH(EDATE(C4,1),C4:C1502,1))/E4)-1 -> 0.0068067727 | K27: =J27*'Portfolio Details'!$D$8 -> 0.0013613545
B28: BANKBEES | C28: 44377 | D28: 352.73 | E28: 350.29 | F28: 352.27 | H28: =E28/D28-1 -> -0.0069174723 | I28: =H28*'Portfolio Details'!$D$8 -> -0.0013834945 | J28: =(INDEX(E5:E1503,MATCH(EDATE(C5,1),C5:C1503,1))/E5)-1 -> 0.004638009 | K28: =J28*'Portfolio Details'!$D$8 -> 0.00092760181
B29: BANKBEES | C29: 44378 | D29: 350.29 | E29: 349.66 | F29: 350.26 | H29: =E29/D29-1 -> -0.0017985098 | I29: =H29*'Portfolio Details'!$D$8 -> -0.00035970196 | J29: =(INDEX(E6:E1504,MATCH(EDATE(C6,1),C6:C1504,1))/E6)-1 -> -0.016370886 | K29: =J29*'Portfolio Details'!$D$8 -> -0.0032741772
B30: BANKBEES | C30: 44379 | D30: 349.66 | E30: 350.53 | F30: 350.12 | H30: =E30/D30-1 -> 0.0024881313 | I30: =H30*'Portfolio Details'!$D$8 -> 0.00049762627 | J30: =(INDEX(E7:E1505,MATCH(EDATE(C7,1),C7:C1505,1))/E7)-1 -> -0.016344558 | K30: =J30*'Portfolio Details'!$D$8 -> -0.0032689116
B31: BANKBEES | C31: 44382 | D31: 350.53 | E31: 353.9 | F31: 352.89 | H31: =E31/D31-1 -> 0.0096140131 | I31: =H31*'Portfolio Details'!$D$8 -> 0.0019228026 | J31: =(INDEX(E8:E1506,MATCH(EDATE(C8,1),C8:C1506,1))/E8)-1 -> -0.014340747 | K31: =J31*'Portfolio Details'!$D$8 -> -0.0028681495
B32: BANKBEES | C32: 44383 | D32: 353.9 | E32: 357.43 | F32: 357.35 | H32: =E32/D32-1 -> 0.0099745691 | I32: =H32*'Portfolio Details'!$D$8 -> 0.0019949138 | J32: =(INDEX(E9:E1507,MATCH(EDATE(C9,1),C9:C1507,1))/E9)-1 -> -0.020647072 | K32: =J32*'Portfolio Details'!$D$8 -> -0.0041294144
B33: BANKBEES | C33: 44384 | D33: 357.43 | E33: 359.2 | F33: 358.14 | H33: =E33/D33-1 -> 0.0049520186 | I33: =H33*'Portfolio Details'!$D$8 -> 0.00099040372 | J33: =(INDEX(E10:E1508,MATCH(EDATE(C10,1),C10:C1508,1))/E10)-1 -> -0.011784274 | K33: =J33*'Portfolio Details'!$D$8 -> -0.0023568549
B34: BANKBEES | C34: 44385 | D34: 359.2 | E34: 355.2 | F34: 356.51 | H34: =E34/D34-1 -> -0.011135857 | I34: =H34*'Portfolio Details'!$D$8 -> -0.0022271715 | J34: =(INDEX(E11:E1509,MATCH(EDATE(C11,1),C11:C1509,1))/E11)-1 -> 0.0089320825 | K34: =J34*'Portfolio Details'!$D$8 -> 0.0017864165
B35: BANKBEES | C35: 44386 | D35: 355.2 | E35: 353.5 | F35: 353.14 | H35: =E35/D35-1 -> -0.004786036 | I35: =H35*'Portfolio Details'!$D$8 -> -0.00095720721 | J35: =(INDEX(E12:E1510,MATCH(EDATE(C12,1),C12:C1510,1))/E12)-1 -> 0.0087183711 | K35: =J35*'Portfolio Details'!$D$8 -> 0.0017436742
B36: BANKBEES | C36: 44389 | D36: 353.5 | E36: 354.18 | F36: 354.96 | H36: =E36/D36-1 -> 0.0019236209 | I36: =H36*'Portfolio Details'!$D$8 -> 0.00038472419 | J36: =(INDEX(E13:E1511,MATCH(EDATE(C13,1),C13:C1511,1))/E13)-1 -> 0.01164754 | K36: =J36*'Portfolio Details'!$D$8 -> 0.0023295081
... B1242: BANKBEES | C1242: 46167 | D1242: 559.62 | E1242: 571.02 | F1242: 568.66 | H1242: =E1242/D1242-1 -> 0.020370966 | I1242: =H1242*'Portfolio Details'!$D$8 -> 0.0040741932 | J1242: =(INDEX(E1219:E2717,MATCH(EDATE(C1219,1),C1219:C2717,1))/E1219)-1 -> -0.065407911 | K1242: =J1242*'Portfolio Details'!$D$8 -> -0.013081582

Sheet ITbees
B1: Symbol | C1: Date | D1: Prev Close | E1: Close Price | F1: Average Price | H1: Daily Returns% | I1: Weighted Returns | J1: Rolling Returns | K1: Weighted Rolling Returns
B2: NETFIT | C2: 44341 | D2: 26.37 | E2: 26.6 | F2: 26.61 | H2: =E2/D2-1 -> 0.0087220326 | I2: =H2*'Portfolio Details'!$D$11 -> 0.00043610163 | L2: Average daily return % | M2: =AVERAGE(H2:H1242) -> 0.00024370615
B3: NETFIT | C3: 44342 | D3: 26.6 | E3: 27.19 | F3: 26.93 | H3: =E3/D3-1 -> 0.022180451 | I3: =H3*'Portfolio Details'!$D$11 -> 0.0011090226
B4: NETFIT | C4: 44343 | D4: 27.19 | E4: 27.37 | F4: 27.47 | H4: =E4/D4-1 -> 0.0066200809 | I4: =H4*'Portfolio Details'!$D$11 -> 0.00033100405 | L4: Average Monthly return % | M4: =M2*20 -> 0.0048741231
B5: NETFIT | C5: 44344 | D5: 27.37 | E5: 27.33 | F5: 27.29 | H5: =E5/D5-1 -> -0.0014614541 | I5: =H5*'Portfolio Details'!$D$11 -> -7.3072707e-05
B6: NETFIT | C6: 44347 | D6: 27.33 | E6: 27.39 | F6: 27.43 | H6: =E6/D6-1 -> 0.0021953897 | I6: =H6*'Portfolio Details'!$D$11 -> 0.00010976948 | L6: Average annual return % | M6: =M2*252 -> 0.061413951
B7: NETFIT | C7: 44348 | D7: 27.39 | E7: 27.45 | F7: 27.31 | H7: =E7/D7-1 -> 0.0021905805 | I7: =H7*'Portfolio Details'!$D$11 -> 0.00010952903
B8: NETFIT | C8: 44349 | D8: 27.45 | E8: 27.29 | F8: 27.25 | H8: =E8/D8-1 -> -0.0058287796 | I8: =H8*'Portfolio Details'!$D$11 -> -0.00029143898 | L8: CAGR% | M8: =(1+(E1242/E2-1))^(1/5)-1 -> 0.038627621
B9: NETFIT | C9: 44350 | D9: 27.29 | E9: 27.33 | F9: 27.35 | H9: =E9/D9-1 -> 0.0014657384 | I9: =H9*'Portfolio Details'!$D$11 -> 7.3286918e-05
B10: NETFIT | C10: 44351 | D10: 27.33 | E10: 27.38 | F10: 27.39 | H10: =E10/D10-1 -> 0.0018294914 | I10: =H10*'Portfolio Details'!$D$11 -> 9.147457e-05 | L10: Risk | M10: =_xlfn.STDEV.P(H2:H1242) -> 0.012953212
B11: NETFIT | C11: 44354 | D11: 27.38 | E11: 27.56 | F11: 27.51 | H11: =E11/D11-1 -> 0.0065741417 | I11: =H11*'Portfolio Details'!$D$11 -> 0.00032870709
B12: NETFIT | C12: 44355 | D12: 27.56 | E12: 28.01 | F12: 27.99 | H12: =E12/D12-1 -> 0.016328012 | I12: =H12*'Portfolio Details'!$D$11 -> 0.00081640058
B13: NETFIT | C13: 44356 | D13: 28.01 | E13: 27.84 | F13: 28.04 | H13: =E13/D13-1 -> -0.006069261 | I13: =H13*'Portfolio Details'!$D$11 -> -0.00030346305
B14: NETFIT | C14: 44357 | D14: 27.84 | E14: 28.1 | F14: 28.05 | H14: =E14/D14-1 -> 0.0093390805 | I14: =H14*'Portfolio Details'!$D$11 -> 0.00046695402
B15: NETFIT | C15: 44358 | D15: 28.1 | E15: 28.64 | F15: 28.54 | H15: =E15/D15-1 -> 0.019217082 | I15: =H15*'Portfolio Details'!$D$11 -> 0.00096085409
B16: NETFIT | C16: 44361 | D16: 28.64 | E16: 28.7 | F16: 28.83 | H16: =E16/D16-1 -> 0.0020949721 | I16: =H16*'Portfolio Details'!$D$11 -> 0.0001047486
B17: NETFIT | C17: 44362 | D17: 28.7 | E17: 28.82 | F17: 28.88 | H17: =E17/D17-1 -> 0.0041811847 | I17: =H17*'Portfolio Details'!$D$11 -> 0.00020905923
B18: NETFIT | C18: 44363 | D18: 28.82 | E18: 28.8 | F18: 28.74 | H18: =E18/D18-1 -> -0.00069396253 | I18: =H18*'Portfolio Details'!$D$11 -> -3.4698126e-05
B19: NETFIT | C19: 44364 | D19: 28.8 | E19: 29.04 | F19: 28.97 | H19: =E19/D19-1 -> 0.0083333333 | I19: =H19*'Portfolio Details'!$D$11 -> 0.00041666667
B20: NETFIT | C20: 44365 | D20: 29.04 | E20: 28.82 | F20: 29 | H20: =E20/D20-1 -> -0.0075757576 | I20: =H20*'Portfolio Details'!$D$11 -> -0.00037878788
B21: NETFIT | C21: 44368 | D21: 28.82 | E21: 28.77 | F21: 28.66 | H21: =E21/D21-1 -> -0.0017349063 | I21: =H21*'Portfolio Details'!$D$11 -> -8.6745316e-05
B22: NETFIT | C22: 44369 | D22: 28.77 | E22: 28.95 | F22: 28.99 | H22: =E22/D22-1 -> 0.0062565172 | I22: =H22*'Portfolio Details'!$D$11 -> 0.00031282586
... B24: NETFIT | C24: 44371 | D24: 28.68 | E24: 29.35 | F24: 29.23 | H24: =E24/D24-1 -> 0.023361227 | I24: =H24*'Portfolio Details'!$D$11 -> 0.0011680614
B25: NETFIT | C25: 44372 | D25: 29.35 | E25: 29.62 | F25: 29.56 | H25: =E25/D25-1 -> 0.0091993186 | I25: =H25*'Portfolio Details'!$D$11 -> 0.00045996593 | J25: =(INDEX(E2:E1500,MATCH(EDATE(C2,1),C2:C1500,1))/E2)-1 -> 0.11353383 | K25: =J25*'Portfolio Details'!$D$11 -> 0.0056766917
B26: NETFIT | C26: 44375 | D26: 29.62 | E26: 29.53 | F26: 29.56 | H26: =E26/D26-1 -> -0.0030384875 | I26: =H26*'Portfolio Details'!$D$11 -> -0.00015192438 | J26: =(INDEX(E3:E1501,MATCH(EDATE(C3,1),C3:C1501,1))/E3)-1 -> 0.089371092 | K26: =J26*'Portfolio Details'!$D$11 -> 0.0044685546
B27: NETFIT | C27: 44376 | D27: 29.53 | E27: 29.45 | F27: 29.54 | H27: =E27/D27-1 -> -0.0027091094 | I27: =H27*'Portfolio Details'!$D$11 -> -0.00013545547 | J27: =(INDEX(E4:E1502,MATCH(EDATE(C4,1),C4:C1502,1))/E4)-1 -> 0.082206796 | K27: =J27*'Portfolio Details'!$D$11 -> 0.0041103398
B28: NETFIT | C28: 44377 | D28: 29.45 | E28: 29.62 | F28: 29.66 | H28: =E28/D28-1 -> 0.0057724958 | I28: =H28*'Portfolio Details'!$D$11 -> 0.00028862479 | J28: =(INDEX(E5:E1503,MATCH(EDATE(C5,1),C5:C1503,1))/E5)-1 -> 0.080497622 | K28: =J28*'Portfolio Details'!$D$11 -> 0.0040248811
B29: NETFIT | C29: 44378 | D29: 29.62 | E29: 29.47 | F29: 29.5 | H29: =E29/D29-1 -> -0.0050641458 | I29: =H29*'Portfolio Details'!$D$11 -> -0.00025320729 | J29: =(INDEX(E6:E1504,MATCH(EDATE(C6,1),C6:C1504,1))/E6)-1 -> 0.081416575 | K29: =J29*'Portfolio Details'!$D$11 -> 0.0040708288
B30: NETFIT | C30: 44379 | D30: 29.47 | E30: 29.46 | F30: 29.32 | H30: =E30/D30-1 -> -0.00033932813 | I30: =H30*'Portfolio Details'!$D$11 -> -1.6966407e-05 | J30: =(INDEX(E7:E1505,MATCH(EDATE(C7,1),C7:C1505,1))/E7)-1 -> 0.073588342 | K30: =J30*'Portfolio Details'!$D$11 -> 0.0036794171
B31: NETFIT | C31: 44382 | D31: 29.46 | E31: 29.41 | F31: 29.51 | H31: =E31/D31-1 -> -0.0016972166 | I31: =H31*'Portfolio Details'!$D$11 -> -8.4860828e-05 | J31: =(INDEX(E8:E1506,MATCH(EDATE(C8,1),C8:C1506,1))/E8)-1 -> 0.079516306 | K31: =J31*'Portfolio Details'!$D$11 -> 0.0039758153
B32: NETFIT | C32: 44383 | D32: 29.41 | E32: 29.11 | F32: 29.28 | H32: =E32/D32-1 -> -0.010200612 | I32: =H32*'Portfolio Details'!$D$11 -> -0.0005100306 | J32: =(INDEX(E9:E1507,MATCH(EDATE(C9,1),C9:C1507,1))/E9)-1 -> 0.077936334 | K32: =J32*'Portfolio Details'!$D$11 -> 0.0038968167
B33: NETFIT | C33: 44384 | D33: 29.11 | E33: 29.18 | F33: 29.08 | H33: =E33/D33-1 -> 0.0024046719 | I33: =H33*'Portfolio Details'!$D$11 -> 0.0001202336 | J33: =(INDEX(E10:E1508,MATCH(EDATE(C10,1),C10:C1508,1))/E10)-1 -> 0.07596786 | K33: =J33*'Portfolio Details'!$D$11 -> 0.003798393
B34: NETFIT | C34: 44385 | D34: 29.18 | E34: 29.16 | F34: 29.17 | H34: =E34/D34-1 -> -0.00068540096 | I34: =H34*'Portfolio Details'!$D$11 -> -3.4270048e-05 | J34: =(INDEX(E11:E1509,MATCH(EDATE(C11,1),C11:C1509,1))/E11)-1 -> 0.058780842 | K34: =J34*'Portfolio Details'!$D$11 -> 0.0029390421
B35: NETFIT | C35: 44386 | D35: 29.16 | E35: 29.09 | F35: 29.12 | H35: =E35/D35-1 -> -0.0024005487 | I35: =H35*'Portfolio Details'!$D$11 -> -0.00012002743 | J35: =(INDEX(E12:E1510,MATCH(EDATE(C12,1),C12:C1510,1))/E12)-1 -> 0.041056765 | K35: =J35*'Portfolio Details'!$D$11 -> 0.0020528383
B36: NETFIT | C36: 44389 | D36: 29.09 | E36: 28.94 | F36: 29.02 | H36: =E36/D36-1 -> -0.0051564111 | I36: =H36*'Portfolio Details'!$D$11 -> -0.00025782056 | J36: =(INDEX(E13:E1511,MATCH(EDATE(C13,1),C13:C1511,1))/E13)-1 -> 0.044899425 | K36: =J36*'Portfolio Details'!$D$11 -> 0.0022449713
... B1242: ITBEES | C1242: 46167 | D1242: 32.02 | E1242: 32.15 | F1242: 32.2 | H1242: =E1242/D1242-1 -> 0.0040599625 | I1242: =H1242*'Portfolio Details'!$D$11 -> 0.00020299813 | J1242: =(INDEX(E1219:E2717,MATCH(EDATE(C1219,1),C1219:C2717,1))/E1219)-1 -> -0.082379863 | K1242: =J1242*'Portfolio Details'!$D$11 -> -0.0041189931

Sheet Healthy
B1: Symbol | C1: Date | D1: Prev Close | E1: Close Price | F1: Average Price | H1: Daily Returns% | I1: Weighted Returns | J1: Rolling Returns | K1: Weighted Rolling Returns
B2: HEALTHY | C2: 44497 | D2: 8.75 | E2: 8.61 | F2: 8.67 | H2: =E2/D2-1 -> -0.016 | I2: =H2*'Portfolio Details'!$D$12 -> -0.0032 | L2: Average daily return % | M2: =AVERAGE(H2:H1134) -> 0.00058372902
B3: HEALTHY | C3: 44498 | D3: 8.61 | E3: 8.67 | F3: 8.66 | H3: =E3/D3-1 -> 0.0069686411 | I3: =H3*'Portfolio Details'!$D$12 -> 0.0013937282
B4: HEALTHY | C4: 44501 | D4: 8.67 | E4: 8.74 | F4: 8.76 | H4: =E4/D4-1 -> 0.0080738178 | I4: =H4*'Portfolio Details'!$D$12 -> 0.0016147636 | L4: Average Monthly return % | M4: =M2*20 -> 0.01167458
B5: HEALTHY | C5: 44502 | D5: 8.74 | E5: 8.64 | F5: 8.65 | H5: =E5/D5-1 -> -0.011441648 | I5: =H5*'Portfolio Details'!$D$12 -> -0.0022883295
B6: HEALTHY | C6: 44503 | D6: 8.64 | E6: 8.63 | F6: 8.67 | H6: =E6/D6-1 -> -0.0011574074 | I6: =H6*'Portfolio Details'!$D$12 -> -0.00023148148 | L6: Average annual return % | M6: =M2*252 -> 0.14709971
B7: HEALTHY | C7: 44504 | D7: 8.63 | E7: 8.67 | F7: 8.69 | H7: =E7/D7-1 -> 0.0046349942 | I7: =H7*'Portfolio Details'!$D$12 -> 0.00092699884
B8: HEALTHY | C8: 44508 | D8: 8.67 | E8: 8.65 | F8: 8.65 | H8: =E8/D8-1 -> -0.0023068051 | I8: =H8*'Portfolio Details'!$D$12 -> -0.00046136101 | L8: CAGR% | M8: =(1+(E1134/E2-1))^(1/5)-1 -> 0.13433511
B9: HEALTHY | C9: 44509 | D9: 8.65 | E9: 8.69 | F9: 8.7 | H9: =E9/D9-1 -> 0.0046242775 | I9: =H9*'Portfolio Details'!$D$12 -> 0.00092485549
B10: HEALTHY | C10: 44510 | D10: 8.69 | E10: 8.65 | F10: 8.68 | H10: =E10/D10-1 -> -0.0046029919 | I10: =H10*'Portfolio Details'!$D$12 -> -0.00092059839 | L10: Risk | M10: =_xlfn.STDEV.P(H2:H1134) -> 0.009116414
B11: HEALTHY | C11: 44511 | D11: 8.65 | E11: 8.69 | F11: 8.71 | H11: =E11/D11-1 -> 0.0046242775 | I11: =H11*'Portfolio Details'!$D$12 -> 0.00092485549
B12: HEALTHY | C12: 44512 | D12: 8.69 | E12: 8.62 | F12: 8.66 | H12: =E12/D12-1 -> -0.0080552359 | I12: =H12*'Portfolio Details'!$D$12 -> -0.0016110472
B13: HEALTHY | C13: 44515 | D13: 8.62 | E13: 8.75 | F13: 8.73 | H13: =E13/D13-1 -> 0.015081206 | I13: =H13*'Portfolio Details'!$D$12 -> 0.0030162413
B14: HEALTHY | C14: 44516 | D14: 8.75 | E14: 8.75 | F14: 8.75 | H14: =E14/D14-1 -> 0 | I14: =H14*'Portfolio Details'!$D$12 -> 0
B15: HEALTHY | C15: 44517 | D15: 8.75 | E15: 8.76 | F15: 8.78 | H15: =E15/D15-1 -> 0.0011428571 | I15: =H15*'Portfolio Details'!$D$12 -> 0.00022857143
B16: HEALTHY | C16: 44518 | D16: 8.76 | E16: 8.66 | F16: 8.71 | H16: =E16/D16-1 -> -0.011415525 | I16: =H16*'Portfolio Details'!$D$12 -> -0.002283105
B17: HEALTHY | C17: 44522 | D17: 8.66 | E17: 8.57 | F17: 8.61 | H17: =E17/D17-1 -> -0.01039261 | I17: =H17*'Portfolio Details'!$D$12 -> -0.0020785219
B18: HEALTHY | C18: 44523 | D18: 8.57 | E18: 8.65 | F18: 8.6 | H18: =E18/D18-1 -> 0.0093348891 | I18: =H18*'Portfolio Details'!$D$12 -> 0.0018669778
B19: HEALTHY | C19: 44524 | D19: 8.65 | E19: 8.61 | F19: 8.64 | H19: =E19/D19-1 -> -0.0046242775 | I19: =H19*'Portfolio Details'!$D$12 -> -0.00092485549
B20: HEALTHY | C20: 44525 | D20: 8.61 | E20: 8.75 | F20: 8.69 | H20: =E20/D20-1 -> 0.016260163 | I20: =H20*'Portfolio Details'!$D$12 -> 0.0032520325
B21: HEALTHY | C21: 44526 | D21: 8.75 | E21: 8.94 | F21: 8.92 | H21: =E21/D21-1 -> 0.021714286 | I21: =H21*'Portfolio Details'!$D$12 -> 0.0043428571
B22: HEALTHY | C22: 44529 | D22: 8.94 | E22: 8.86 | F22: 8.98 | H22: =E22/D22-1 -> -0.0089485459 | I22: =H22*'Portfolio Details'!$D$12 -> -0.0017897092
... B24: HEALTHY | C24: 44531 | D24: 8.8 | E24: 8.69 | F24: 8.76 | H24: =E24/D24-1 -> -0.0125 | I24: =H24*'Portfolio Details'!$D$12 -> -0.0025
B25: HEALTHY | C25: 44532 | D25: 8.69 | E25: 8.77 | F25: 8.76 | H25: =E25/D25-1 -> 0.0092059839 | I25: =H25*'Portfolio Details'!$D$12 -> 0.0018411968 | J25: =(INDEX(E2:E1500,MATCH(EDATE(C2,1),C2:C1500,1))/E2)-1 -> 0.038327526 | K25: =J25*'Portfolio Details'!$D$12 -> 0.0076655052
B26: HEALTHY | C26: 44533 | D26: 8.77 | E26: 8.65 | F26: 8.68 | H26: =E26/D26-1 -> -0.01368301 | I26: =H26*'Portfolio Details'!$D$12 -> -0.0027366021 | J26: =(INDEX(E3:E1501,MATCH(EDATE(C3,1),C3:C1501,1))/E3)-1 -> 0.021914648 | K26: =J26*'Portfolio Details'!$D$12 -> 0.0043829296
B27: HEALTHY | C27: 44536 | D27: 8.65 | E27: 8.49 | F27: 8.56 | H27: =E27/D27-1 -> -0.01849711 | I27: =H27*'Portfolio Details'!$D$12 -> -0.003699422 | J27: =(INDEX(E4:E1502,MATCH(EDATE(C4,1),C4:C1502,1))/E4)-1 -> -0.0057208238 | K27: =J27*'Portfolio Details'!$D$12 -> -0.0011441648
B28: HEALTHY | C28: 44537 | D28: 8.49 | E28: 8.5 | F28: 8.51 | H28: =E28/D28-1 -> 0.0011778563 | I28: =H28*'Portfolio Details'!$D$12 -> 0.00023557126 | J28: =(INDEX(E5:E1503,MATCH(EDATE(C5,1),C5:C1503,1))/E5)-1 -> 0.015046296 | K28: =J28*'Portfolio Details'!$D$12 -> 0.0030092593
B29: HEALTHY | C29: 44538 | D29: 8.5 | E29: 8.58 | F29: 8.57 | H29: =E29/D29-1 -> 0.0094117647 | I29: =H29*'Portfolio Details'!$D$12 -> 0.0018823529 | J29: =(INDEX(E6:E1504,MATCH(EDATE(C6,1),C6:C1504,1))/E6)-1 -> 0.0023174971 | K29: =J29*'Portfolio Details'!$D$12 -> 0.00046349942
B30: HEALTHY | C30: 44539 | D30: 8.58 | E30: 8.59 | F30: 8.6 | H30: =E30/D30-1 -> 0.0011655012 | I30: =H30*'Portfolio Details'!$D$12 -> 0.00023310023 | J30: =(INDEX(E7:E1505,MATCH(EDATE(C7,1),C7:C1505,1))/E7)-1 -> -0.0023068051 | K30: =J30*'Portfolio Details'!$D$12 -> -0.00046136101
B31: HEALTHY | C31: 44540 | D31: 8.59 | E31: 8.59 | F31: 8.62 | H31: =E31/D31-1 -> 0 | I31: =H31*'Portfolio Details'!$D$12 -> 0 | J31: =(INDEX(E8:E1506,MATCH(EDATE(C8,1),C8:C1506,1))/E8)-1 -> -0.0080924855 | K31: =J31*'Portfolio Details'!$D$12 -> -0.0016184971
B32: HEALTHY | C32: 44543 | D32: 8.59 | E32: 8.57 | F32: 8.6 | H32: =E32/D32-1 -> -0.0023282887 | I32: =H32*'Portfolio Details'!$D$12 -> -0.00046565774 | J32: =(INDEX(E9:E1507,MATCH(EDATE(C9,1),C9:C1507,1))/E9)-1 -> -0.01150748 | K32: =J32*'Portfolio Details'!$D$12 -> -0.002301496
